{
 "cells": [
  {
   "cell_type": "code",
   "execution_count": 1,
   "metadata": {},
   "outputs": [],
   "source": [
    "import pandas as pd\n",
    "import numpy as np"
   ]
  },
  {
   "cell_type": "code",
   "execution_count": 2,
   "metadata": {},
   "outputs": [],
   "source": [
    "df_faq = pd.read_csv('faq-data/df_faq.csv', index_col=0)"
   ]
  },
  {
   "cell_type": "code",
   "execution_count": 3,
   "metadata": {},
   "outputs": [],
   "source": [
    "questions = df_faq['Question']"
   ]
  },
  {
   "cell_type": "code",
   "execution_count": 4,
   "metadata": {},
   "outputs": [
    {
     "data": {
      "text/html": [
       "<div>\n",
       "<style scoped>\n",
       "    .dataframe tbody tr th:only-of-type {\n",
       "        vertical-align: middle;\n",
       "    }\n",
       "\n",
       "    .dataframe tbody tr th {\n",
       "        vertical-align: top;\n",
       "    }\n",
       "\n",
       "    .dataframe thead th {\n",
       "        text-align: right;\n",
       "    }\n",
       "</style>\n",
       "<table border=\"1\" class=\"dataframe\">\n",
       "  <thead>\n",
       "    <tr style=\"text-align: right;\">\n",
       "      <th></th>\n",
       "      <th>Question</th>\n",
       "      <th>Answer</th>\n",
       "      <th>Type</th>\n",
       "    </tr>\n",
       "  </thead>\n",
       "  <tbody>\n",
       "    <tr>\n",
       "      <th>0</th>\n",
       "      <td>(HKDSE) How do I apply to HKU through JUPAS sc...</td>\n",
       "      <td>(HKDSE) We welcome your application to HKU thr...</td>\n",
       "      <td>HKDSE</td>\n",
       "    </tr>\n",
       "    <tr>\n",
       "      <th>1</th>\n",
       "      <td>(HKDSE) What are the common mistakes as a JUPA...</td>\n",
       "      <td>(HKDSE) Students should not forget that in add...</td>\n",
       "      <td>HKDSE</td>\n",
       "    </tr>\n",
       "    <tr>\n",
       "      <th>2</th>\n",
       "      <td>(HKDSE) How can I apply to HKU as a HKDSE repe...</td>\n",
       "      <td>(HKDSE) All students who apply to HKU on the b...</td>\n",
       "      <td>HKDSE</td>\n",
       "    </tr>\n",
       "    <tr>\n",
       "      <th>3</th>\n",
       "      <td>(HKDSE) What are the minimum university entran...</td>\n",
       "      <td>(HKDSE) To have your application considered fo...</td>\n",
       "      <td>HKDSE</td>\n",
       "    </tr>\n",
       "    <tr>\n",
       "      <th>4</th>\n",
       "      <td>(HKDSE) How is the admission score calculated?</td>\n",
       "      <td>(HKDSE) Starting from the academic year 2020/2...</td>\n",
       "      <td>HKDSE</td>\n",
       "    </tr>\n",
       "  </tbody>\n",
       "</table>\n",
       "</div>"
      ],
      "text/plain": [
       "                                            Question  \\\n",
       "0  (HKDSE) How do I apply to HKU through JUPAS sc...   \n",
       "1  (HKDSE) What are the common mistakes as a JUPA...   \n",
       "2  (HKDSE) How can I apply to HKU as a HKDSE repe...   \n",
       "3  (HKDSE) What are the minimum university entran...   \n",
       "4     (HKDSE) How is the admission score calculated?   \n",
       "\n",
       "                                              Answer   Type  \n",
       "0  (HKDSE) We welcome your application to HKU thr...  HKDSE  \n",
       "1  (HKDSE) Students should not forget that in add...  HKDSE  \n",
       "2  (HKDSE) All students who apply to HKU on the b...  HKDSE  \n",
       "3  (HKDSE) To have your application considered fo...  HKDSE  \n",
       "4  (HKDSE) Starting from the academic year 2020/2...  HKDSE  "
      ]
     },
     "execution_count": 4,
     "metadata": {},
     "output_type": "execute_result"
    }
   ],
   "source": [
    "df_faq.head(5)"
   ]
  },
  {
   "cell_type": "code",
   "execution_count": null,
   "metadata": {},
   "outputs": [],
   "source": []
  },
  {
   "cell_type": "code",
   "execution_count": 5,
   "metadata": {},
   "outputs": [
    {
     "name": "stderr",
     "output_type": "stream",
     "text": [
      "ERROR:root:Internal Python error in the inspect module.\n",
      "Below is the traceback from this internal error.\n",
      "\n",
      "ERROR:root:Internal Python error in the inspect module.\n",
      "Below is the traceback from this internal error.\n",
      "\n",
      "ERROR:root:Internal Python error in the inspect module.\n",
      "Below is the traceback from this internal error.\n",
      "\n"
     ]
    },
    {
     "name": "stdout",
     "output_type": "stream",
     "text": [
      "Traceback (most recent call last):\n",
      "  File \"c:\\Users\\Kackie\\anaconda3\\envs\\tensorflow-1.15\\lib\\site-packages\\IPython\\core\\interactiveshell.py\", line 3552, in run_code\n",
      "    exec(code_obj, self.user_global_ns, self.user_ns)\n",
      "  File \"C:\\Users\\Kackie\\AppData\\Local\\Temp\\ipykernel_28924\\3793406994.py\", line 1, in <module>\n",
      "    import tensorflow as tf\n",
      "  File \"c:\\Users\\Kackie\\anaconda3\\envs\\tensorflow-1.15\\lib\\site-packages\\tensorflow\\__init__.py\", line 99, in <module>\n",
      "    from tensorflow_core import *\n",
      "  File \"c:\\Users\\Kackie\\anaconda3\\envs\\tensorflow-1.15\\lib\\site-packages\\tensorflow_core\\__init__.py\", line 28, in <module>\n",
      "    from tensorflow.python import pywrap_tensorflow  # pylint: disable=unused-import\n",
      "  File \"<frozen importlib._bootstrap>\", line 1019, in _handle_fromlist\n",
      "  File \"c:\\Users\\Kackie\\anaconda3\\envs\\tensorflow-1.15\\lib\\site-packages\\tensorflow\\__init__.py\", line 50, in __getattr__\n",
      "    module = self._load()\n",
      "  File \"c:\\Users\\Kackie\\anaconda3\\envs\\tensorflow-1.15\\lib\\site-packages\\tensorflow\\__init__.py\", line 44, in _load\n",
      "    module = _importlib.import_module(self.__name__)\n",
      "  File \"c:\\Users\\Kackie\\anaconda3\\envs\\tensorflow-1.15\\lib\\importlib\\__init__.py\", line 127, in import_module\n",
      "    return _bootstrap._gcd_import(name[level:], package, level)\n",
      "  File \"c:\\Users\\Kackie\\anaconda3\\envs\\tensorflow-1.15\\lib\\site-packages\\tensorflow_core\\python\\__init__.py\", line 52, in <module>\n",
      "    from tensorflow.core.framework.graph_pb2 import *\n",
      "  File \"c:\\Users\\Kackie\\anaconda3\\envs\\tensorflow-1.15\\lib\\site-packages\\tensorflow_core\\core\\framework\\graph_pb2.py\", line 16, in <module>\n",
      "    from tensorflow.core.framework import node_def_pb2 as tensorflow_dot_core_dot_framework_dot_node__def__pb2\n",
      "  File \"c:\\Users\\Kackie\\anaconda3\\envs\\tensorflow-1.15\\lib\\site-packages\\tensorflow_core\\core\\framework\\node_def_pb2.py\", line 16, in <module>\n",
      "    from tensorflow.core.framework import attr_value_pb2 as tensorflow_dot_core_dot_framework_dot_attr__value__pb2\n",
      "  File \"c:\\Users\\Kackie\\anaconda3\\envs\\tensorflow-1.15\\lib\\site-packages\\tensorflow_core\\core\\framework\\attr_value_pb2.py\", line 16, in <module>\n",
      "    from tensorflow.core.framework import tensor_pb2 as tensorflow_dot_core_dot_framework_dot_tensor__pb2\n",
      "  File \"c:\\Users\\Kackie\\anaconda3\\envs\\tensorflow-1.15\\lib\\site-packages\\tensorflow_core\\core\\framework\\tensor_pb2.py\", line 16, in <module>\n",
      "    from tensorflow.core.framework import resource_handle_pb2 as tensorflow_dot_core_dot_framework_dot_resource__handle__pb2\n",
      "  File \"c:\\Users\\Kackie\\anaconda3\\envs\\tensorflow-1.15\\lib\\site-packages\\tensorflow_core\\core\\framework\\resource_handle_pb2.py\", line 16, in <module>\n",
      "    from tensorflow.core.framework import tensor_shape_pb2 as tensorflow_dot_core_dot_framework_dot_tensor__shape__pb2\n",
      "  File \"c:\\Users\\Kackie\\anaconda3\\envs\\tensorflow-1.15\\lib\\site-packages\\tensorflow_core\\core\\framework\\tensor_shape_pb2.py\", line 42, in <module>\n",
      "    serialized_options=None, file=DESCRIPTOR),\n",
      "  File \"c:\\Users\\Kackie\\anaconda3\\envs\\tensorflow-1.15\\lib\\site-packages\\google\\protobuf\\descriptor.py\", line 560, in __new__\n",
      "    _message.Message._CheckCalledFromGeneratedFile()\n",
      "TypeError: Descriptors cannot not be created directly.\n",
      "If this call came from a _pb2.py file, your generated code is out of date and must be regenerated with protoc >= 3.19.0.\n",
      "If you cannot immediately regenerate your protos, some other possible workarounds are:\n",
      " 1. Downgrade the protobuf package to 3.20.x or lower.\n",
      " 2. Set PROTOCOL_BUFFERS_PYTHON_IMPLEMENTATION=python (but this will use pure-Python parsing and will be much slower).\n",
      "\n",
      "More information: https://developers.google.com/protocol-buffers/docs/news/2022-05-06#python-updates\n",
      "\n",
      "During handling of the above exception, another exception occurred:\n",
      "\n",
      "Traceback (most recent call last):\n",
      "  File \"c:\\Users\\Kackie\\anaconda3\\envs\\tensorflow-1.15\\lib\\site-packages\\IPython\\core\\interactiveshell.py\", line 2098, in showtraceback\n",
      "    stb = value._render_traceback_()\n",
      "AttributeError: 'TypeError' object has no attribute '_render_traceback_'\n",
      "\n",
      "During handling of the above exception, another exception occurred:\n",
      "\n",
      "Traceback (most recent call last):\n",
      "  File \"c:\\Users\\Kackie\\anaconda3\\envs\\tensorflow-1.15\\lib\\site-packages\\IPython\\core\\ultratb.py\", line 1101, in get_records\n",
      "    return _fixed_getinnerframes(etb, number_of_lines_of_context, tb_offset)\n",
      "  File \"c:\\Users\\Kackie\\anaconda3\\envs\\tensorflow-1.15\\lib\\site-packages\\IPython\\core\\ultratb.py\", line 248, in wrapped\n",
      "    return f(*args, **kwargs)\n",
      "  File \"c:\\Users\\Kackie\\anaconda3\\envs\\tensorflow-1.15\\lib\\site-packages\\IPython\\core\\ultratb.py\", line 281, in _fixed_getinnerframes\n",
      "    records = fix_frame_records_filenames(inspect.getinnerframes(etb, context))\n",
      "  File \"c:\\Users\\Kackie\\anaconda3\\envs\\tensorflow-1.15\\lib\\inspect.py\", line 1502, in getinnerframes\n",
      "    frameinfo = (tb.tb_frame,) + getframeinfo(tb, context)\n",
      "  File \"c:\\Users\\Kackie\\anaconda3\\envs\\tensorflow-1.15\\lib\\inspect.py\", line 1460, in getframeinfo\n",
      "    filename = getsourcefile(frame) or getfile(frame)\n",
      "  File \"c:\\Users\\Kackie\\anaconda3\\envs\\tensorflow-1.15\\lib\\inspect.py\", line 696, in getsourcefile\n",
      "    if getattr(getmodule(object, filename), '__loader__', None) is not None:\n",
      "  File \"c:\\Users\\Kackie\\anaconda3\\envs\\tensorflow-1.15\\lib\\inspect.py\", line 733, in getmodule\n",
      "    if ismodule(module) and hasattr(module, '__file__'):\n",
      "  File \"c:\\Users\\Kackie\\anaconda3\\envs\\tensorflow-1.15\\lib\\site-packages\\tensorflow\\__init__.py\", line 50, in __getattr__\n",
      "    module = self._load()\n",
      "  File \"c:\\Users\\Kackie\\anaconda3\\envs\\tensorflow-1.15\\lib\\site-packages\\tensorflow\\__init__.py\", line 44, in _load\n",
      "    module = _importlib.import_module(self.__name__)\n",
      "  File \"c:\\Users\\Kackie\\anaconda3\\envs\\tensorflow-1.15\\lib\\importlib\\__init__.py\", line 127, in import_module\n",
      "    return _bootstrap._gcd_import(name[level:], package, level)\n",
      "  File \"<frozen importlib._bootstrap>\", line 1006, in _gcd_import\n",
      "  File \"<frozen importlib._bootstrap>\", line 983, in _find_and_load\n",
      "  File \"<frozen importlib._bootstrap>\", line 953, in _find_and_load_unlocked\n",
      "  File \"<frozen importlib._bootstrap>\", line 219, in _call_with_frames_removed\n",
      "  File \"<frozen importlib._bootstrap>\", line 1006, in _gcd_import\n",
      "  File \"<frozen importlib._bootstrap>\", line 983, in _find_and_load\n",
      "  File \"<frozen importlib._bootstrap>\", line 967, in _find_and_load_unlocked\n",
      "  File \"<frozen importlib._bootstrap>\", line 677, in _load_unlocked\n",
      "  File \"<frozen importlib._bootstrap_external>\", line 728, in exec_module\n",
      "  File \"<frozen importlib._bootstrap>\", line 219, in _call_with_frames_removed\n",
      "  File \"c:\\Users\\Kackie\\anaconda3\\envs\\tensorflow-1.15\\lib\\site-packages\\tensorflow_core\\__init__.py\", line 33, in <module>\n",
      "    from tensorflow._api.v1 import audio\n",
      "  File \"c:\\Users\\Kackie\\anaconda3\\envs\\tensorflow-1.15\\lib\\site-packages\\tensorflow_core\\_api\\v1\\audio\\__init__.py\", line 10, in <module>\n",
      "    from tensorflow.python.ops.gen_audio_ops import decode_wav\n",
      "  File \"c:\\Users\\Kackie\\anaconda3\\envs\\tensorflow-1.15\\lib\\site-packages\\tensorflow_core\\python\\ops\\gen_audio_ops.py\", line 11, in <module>\n",
      "    from tensorflow.python.eager import context as _context\n",
      "  File \"c:\\Users\\Kackie\\anaconda3\\envs\\tensorflow-1.15\\lib\\site-packages\\tensorflow_core\\python\\eager\\context.py\", line 29, in <module>\n",
      "    from tensorflow.core.protobuf import config_pb2\n",
      "  File \"c:\\Users\\Kackie\\anaconda3\\envs\\tensorflow-1.15\\lib\\site-packages\\tensorflow_core\\core\\protobuf\\config_pb2.py\", line 16, in <module>\n",
      "    from tensorflow.core.framework import cost_graph_pb2 as tensorflow_dot_core_dot_framework_dot_cost__graph__pb2\n",
      "  File \"c:\\Users\\Kackie\\anaconda3\\envs\\tensorflow-1.15\\lib\\site-packages\\tensorflow_core\\core\\framework\\cost_graph_pb2.py\", line 16, in <module>\n",
      "    from tensorflow.core.framework import tensor_shape_pb2 as tensorflow_dot_core_dot_framework_dot_tensor__shape__pb2\n",
      "  File \"c:\\Users\\Kackie\\anaconda3\\envs\\tensorflow-1.15\\lib\\site-packages\\tensorflow_core\\core\\framework\\tensor_shape_pb2.py\", line 42, in <module>\n",
      "    serialized_options=None, file=DESCRIPTOR),\n",
      "  File \"c:\\Users\\Kackie\\anaconda3\\envs\\tensorflow-1.15\\lib\\site-packages\\google\\protobuf\\descriptor.py\", line 560, in __new__\n",
      "    _message.Message._CheckCalledFromGeneratedFile()\n",
      "TypeError: Descriptors cannot not be created directly.\n",
      "If this call came from a _pb2.py file, your generated code is out of date and must be regenerated with protoc >= 3.19.0.\n",
      "If you cannot immediately regenerate your protos, some other possible workarounds are:\n",
      " 1. Downgrade the protobuf package to 3.20.x or lower.\n",
      " 2. Set PROTOCOL_BUFFERS_PYTHON_IMPLEMENTATION=python (but this will use pure-Python parsing and will be much slower).\n",
      "\n",
      "More information: https://developers.google.com/protocol-buffers/docs/news/2022-05-06#python-updates\n",
      "Traceback (most recent call last):\n",
      "  File \"c:\\Users\\Kackie\\anaconda3\\envs\\tensorflow-1.15\\lib\\site-packages\\IPython\\core\\interactiveshell.py\", line 3552, in run_code\n",
      "    exec(code_obj, self.user_global_ns, self.user_ns)\n",
      "  File \"C:\\Users\\Kackie\\AppData\\Local\\Temp\\ipykernel_28924\\3793406994.py\", line 1, in <module>\n",
      "    import tensorflow as tf\n",
      "  File \"c:\\Users\\Kackie\\anaconda3\\envs\\tensorflow-1.15\\lib\\site-packages\\tensorflow\\__init__.py\", line 99, in <module>\n",
      "    from tensorflow_core import *\n",
      "  File \"c:\\Users\\Kackie\\anaconda3\\envs\\tensorflow-1.15\\lib\\site-packages\\tensorflow_core\\__init__.py\", line 28, in <module>\n",
      "    from tensorflow.python import pywrap_tensorflow  # pylint: disable=unused-import\n",
      "  File \"<frozen importlib._bootstrap>\", line 1019, in _handle_fromlist\n",
      "  File \"c:\\Users\\Kackie\\anaconda3\\envs\\tensorflow-1.15\\lib\\site-packages\\tensorflow\\__init__.py\", line 50, in __getattr__\n",
      "    module = self._load()\n",
      "  File \"c:\\Users\\Kackie\\anaconda3\\envs\\tensorflow-1.15\\lib\\site-packages\\tensorflow\\__init__.py\", line 44, in _load\n",
      "    module = _importlib.import_module(self.__name__)\n",
      "  File \"c:\\Users\\Kackie\\anaconda3\\envs\\tensorflow-1.15\\lib\\importlib\\__init__.py\", line 127, in import_module\n",
      "    return _bootstrap._gcd_import(name[level:], package, level)\n",
      "  File \"c:\\Users\\Kackie\\anaconda3\\envs\\tensorflow-1.15\\lib\\site-packages\\tensorflow_core\\python\\__init__.py\", line 52, in <module>\n",
      "    from tensorflow.core.framework.graph_pb2 import *\n",
      "  File \"c:\\Users\\Kackie\\anaconda3\\envs\\tensorflow-1.15\\lib\\site-packages\\tensorflow_core\\core\\framework\\graph_pb2.py\", line 16, in <module>\n",
      "    from tensorflow.core.framework import node_def_pb2 as tensorflow_dot_core_dot_framework_dot_node__def__pb2\n",
      "  File \"c:\\Users\\Kackie\\anaconda3\\envs\\tensorflow-1.15\\lib\\site-packages\\tensorflow_core\\core\\framework\\node_def_pb2.py\", line 16, in <module>\n",
      "    from tensorflow.core.framework import attr_value_pb2 as tensorflow_dot_core_dot_framework_dot_attr__value__pb2\n",
      "  File \"c:\\Users\\Kackie\\anaconda3\\envs\\tensorflow-1.15\\lib\\site-packages\\tensorflow_core\\core\\framework\\attr_value_pb2.py\", line 16, in <module>\n",
      "    from tensorflow.core.framework import tensor_pb2 as tensorflow_dot_core_dot_framework_dot_tensor__pb2\n",
      "  File \"c:\\Users\\Kackie\\anaconda3\\envs\\tensorflow-1.15\\lib\\site-packages\\tensorflow_core\\core\\framework\\tensor_pb2.py\", line 16, in <module>\n",
      "    from tensorflow.core.framework import resource_handle_pb2 as tensorflow_dot_core_dot_framework_dot_resource__handle__pb2\n",
      "  File \"c:\\Users\\Kackie\\anaconda3\\envs\\tensorflow-1.15\\lib\\site-packages\\tensorflow_core\\core\\framework\\resource_handle_pb2.py\", line 16, in <module>\n",
      "    from tensorflow.core.framework import tensor_shape_pb2 as tensorflow_dot_core_dot_framework_dot_tensor__shape__pb2\n",
      "  File \"c:\\Users\\Kackie\\anaconda3\\envs\\tensorflow-1.15\\lib\\site-packages\\tensorflow_core\\core\\framework\\tensor_shape_pb2.py\", line 42, in <module>\n",
      "    serialized_options=None, file=DESCRIPTOR),\n",
      "  File \"c:\\Users\\Kackie\\anaconda3\\envs\\tensorflow-1.15\\lib\\site-packages\\google\\protobuf\\descriptor.py\", line 560, in __new__\n",
      "    _message.Message._CheckCalledFromGeneratedFile()\n",
      "TypeError: Descriptors cannot not be created directly.\n",
      "If this call came from a _pb2.py file, your generated code is out of date and must be regenerated with protoc >= 3.19.0.\n",
      "If you cannot immediately regenerate your protos, some other possible workarounds are:\n",
      " 1. Downgrade the protobuf package to 3.20.x or lower.\n",
      " 2. Set PROTOCOL_BUFFERS_PYTHON_IMPLEMENTATION=python (but this will use pure-Python parsing and will be much slower).\n",
      "\n",
      "More information: https://developers.google.com/protocol-buffers/docs/news/2022-05-06#python-updates\n",
      "\n",
      "During handling of the above exception, another exception occurred:\n",
      "\n",
      "Traceback (most recent call last):\n",
      "  File \"c:\\Users\\Kackie\\anaconda3\\envs\\tensorflow-1.15\\lib\\site-packages\\IPython\\core\\interactiveshell.py\", line 2098, in showtraceback\n",
      "    stb = value._render_traceback_()\n",
      "AttributeError: 'TypeError' object has no attribute '_render_traceback_'\n",
      "\n",
      "During handling of the above exception, another exception occurred:\n",
      "\n",
      "Traceback (most recent call last):\n",
      "  File \"c:\\Users\\Kackie\\anaconda3\\envs\\tensorflow-1.15\\lib\\site-packages\\IPython\\core\\interactiveshell.py\", line 3472, in run_ast_nodes\n",
      "    if (await self.run_code(code, result,  async_=asy)):\n",
      "  File \"c:\\Users\\Kackie\\anaconda3\\envs\\tensorflow-1.15\\lib\\site-packages\\IPython\\core\\interactiveshell.py\", line 3569, in run_code\n",
      "    self.showtraceback(running_compiled_code=True)\n",
      "  File \"c:\\Users\\Kackie\\anaconda3\\envs\\tensorflow-1.15\\lib\\site-packages\\IPython\\core\\interactiveshell.py\", line 2101, in showtraceback\n",
      "    value, tb, tb_offset=tb_offset)\n",
      "  File \"c:\\Users\\Kackie\\anaconda3\\envs\\tensorflow-1.15\\lib\\site-packages\\IPython\\core\\ultratb.py\", line 1368, in structured_traceback\n",
      "    self, etype, value, tb, tb_offset, number_of_lines_of_context)\n",
      "  File \"c:\\Users\\Kackie\\anaconda3\\envs\\tensorflow-1.15\\lib\\site-packages\\IPython\\core\\ultratb.py\", line 1268, in structured_traceback\n",
      "    self, etype, value, tb, tb_offset, number_of_lines_of_context\n",
      "  File \"c:\\Users\\Kackie\\anaconda3\\envs\\tensorflow-1.15\\lib\\site-packages\\IPython\\core\\ultratb.py\", line 1125, in structured_traceback\n",
      "    tb_offset)\n",
      "  File \"c:\\Users\\Kackie\\anaconda3\\envs\\tensorflow-1.15\\lib\\site-packages\\IPython\\core\\ultratb.py\", line 1082, in format_exception_as_a_whole\n",
      "    last_unique, recursion_repeat = find_recursion(orig_etype, evalue, records)\n",
      "  File \"c:\\Users\\Kackie\\anaconda3\\envs\\tensorflow-1.15\\lib\\site-packages\\IPython\\core\\ultratb.py\", line 382, in find_recursion\n",
      "    return len(records), 0\n",
      "TypeError: object of type 'NoneType' has no len()\n",
      "\n",
      "During handling of the above exception, another exception occurred:\n",
      "\n",
      "Traceback (most recent call last):\n",
      "  File \"c:\\Users\\Kackie\\anaconda3\\envs\\tensorflow-1.15\\lib\\site-packages\\IPython\\core\\interactiveshell.py\", line 2098, in showtraceback\n",
      "    stb = value._render_traceback_()\n",
      "AttributeError: 'TypeError' object has no attribute '_render_traceback_'\n",
      "\n",
      "During handling of the above exception, another exception occurred:\n",
      "\n",
      "Traceback (most recent call last):\n",
      "  File \"c:\\Users\\Kackie\\anaconda3\\envs\\tensorflow-1.15\\lib\\site-packages\\IPython\\core\\ultratb.py\", line 1101, in get_records\n",
      "    return _fixed_getinnerframes(etb, number_of_lines_of_context, tb_offset)\n",
      "  File \"c:\\Users\\Kackie\\anaconda3\\envs\\tensorflow-1.15\\lib\\site-packages\\IPython\\core\\ultratb.py\", line 248, in wrapped\n",
      "    return f(*args, **kwargs)\n",
      "  File \"c:\\Users\\Kackie\\anaconda3\\envs\\tensorflow-1.15\\lib\\site-packages\\IPython\\core\\ultratb.py\", line 281, in _fixed_getinnerframes\n",
      "    records = fix_frame_records_filenames(inspect.getinnerframes(etb, context))\n",
      "  File \"c:\\Users\\Kackie\\anaconda3\\envs\\tensorflow-1.15\\lib\\inspect.py\", line 1502, in getinnerframes\n",
      "    frameinfo = (tb.tb_frame,) + getframeinfo(tb, context)\n",
      "  File \"c:\\Users\\Kackie\\anaconda3\\envs\\tensorflow-1.15\\lib\\inspect.py\", line 1460, in getframeinfo\n",
      "    filename = getsourcefile(frame) or getfile(frame)\n",
      "  File \"c:\\Users\\Kackie\\anaconda3\\envs\\tensorflow-1.15\\lib\\inspect.py\", line 696, in getsourcefile\n",
      "    if getattr(getmodule(object, filename), '__loader__', None) is not None:\n",
      "  File \"c:\\Users\\Kackie\\anaconda3\\envs\\tensorflow-1.15\\lib\\inspect.py\", line 733, in getmodule\n",
      "    if ismodule(module) and hasattr(module, '__file__'):\n",
      "  File \"c:\\Users\\Kackie\\anaconda3\\envs\\tensorflow-1.15\\lib\\site-packages\\tensorflow\\__init__.py\", line 50, in __getattr__\n",
      "    module = self._load()\n",
      "  File \"c:\\Users\\Kackie\\anaconda3\\envs\\tensorflow-1.15\\lib\\site-packages\\tensorflow\\__init__.py\", line 44, in _load\n",
      "    module = _importlib.import_module(self.__name__)\n",
      "  File \"c:\\Users\\Kackie\\anaconda3\\envs\\tensorflow-1.15\\lib\\importlib\\__init__.py\", line 127, in import_module\n",
      "    return _bootstrap._gcd_import(name[level:], package, level)\n",
      "  File \"<frozen importlib._bootstrap>\", line 1006, in _gcd_import\n",
      "  File \"<frozen importlib._bootstrap>\", line 983, in _find_and_load\n",
      "  File \"<frozen importlib._bootstrap>\", line 953, in _find_and_load_unlocked\n",
      "  File \"<frozen importlib._bootstrap>\", line 219, in _call_with_frames_removed\n",
      "  File \"<frozen importlib._bootstrap>\", line 1006, in _gcd_import\n",
      "  File \"<frozen importlib._bootstrap>\", line 983, in _find_and_load\n",
      "  File \"<frozen importlib._bootstrap>\", line 967, in _find_and_load_unlocked\n",
      "  File \"<frozen importlib._bootstrap>\", line 677, in _load_unlocked\n",
      "  File \"<frozen importlib._bootstrap_external>\", line 728, in exec_module\n",
      "  File \"<frozen importlib._bootstrap>\", line 219, in _call_with_frames_removed\n",
      "  File \"c:\\Users\\Kackie\\anaconda3\\envs\\tensorflow-1.15\\lib\\site-packages\\tensorflow_core\\__init__.py\", line 33, in <module>\n",
      "    from tensorflow._api.v1 import audio\n",
      "  File \"c:\\Users\\Kackie\\anaconda3\\envs\\tensorflow-1.15\\lib\\site-packages\\tensorflow_core\\_api\\v1\\audio\\__init__.py\", line 10, in <module>\n",
      "    from tensorflow.python.ops.gen_audio_ops import decode_wav\n",
      "  File \"c:\\Users\\Kackie\\anaconda3\\envs\\tensorflow-1.15\\lib\\site-packages\\tensorflow_core\\python\\ops\\gen_audio_ops.py\", line 11, in <module>\n",
      "    from tensorflow.python.eager import context as _context\n",
      "  File \"c:\\Users\\Kackie\\anaconda3\\envs\\tensorflow-1.15\\lib\\site-packages\\tensorflow_core\\python\\eager\\context.py\", line 29, in <module>\n",
      "    from tensorflow.core.protobuf import config_pb2\n",
      "  File \"c:\\Users\\Kackie\\anaconda3\\envs\\tensorflow-1.15\\lib\\site-packages\\tensorflow_core\\core\\protobuf\\config_pb2.py\", line 16, in <module>\n",
      "    from tensorflow.core.framework import cost_graph_pb2 as tensorflow_dot_core_dot_framework_dot_cost__graph__pb2\n",
      "  File \"c:\\Users\\Kackie\\anaconda3\\envs\\tensorflow-1.15\\lib\\site-packages\\tensorflow_core\\core\\framework\\cost_graph_pb2.py\", line 16, in <module>\n",
      "    from tensorflow.core.framework import tensor_shape_pb2 as tensorflow_dot_core_dot_framework_dot_tensor__shape__pb2\n",
      "  File \"c:\\Users\\Kackie\\anaconda3\\envs\\tensorflow-1.15\\lib\\site-packages\\tensorflow_core\\core\\framework\\tensor_shape_pb2.py\", line 42, in <module>\n",
      "    serialized_options=None, file=DESCRIPTOR),\n",
      "  File \"c:\\Users\\Kackie\\anaconda3\\envs\\tensorflow-1.15\\lib\\site-packages\\google\\protobuf\\descriptor.py\", line 560, in __new__\n",
      "    _message.Message._CheckCalledFromGeneratedFile()\n",
      "TypeError: Descriptors cannot not be created directly.\n",
      "If this call came from a _pb2.py file, your generated code is out of date and must be regenerated with protoc >= 3.19.0.\n",
      "If you cannot immediately regenerate your protos, some other possible workarounds are:\n",
      " 1. Downgrade the protobuf package to 3.20.x or lower.\n",
      " 2. Set PROTOCOL_BUFFERS_PYTHON_IMPLEMENTATION=python (but this will use pure-Python parsing and will be much slower).\n",
      "\n",
      "More information: https://developers.google.com/protocol-buffers/docs/news/2022-05-06#python-updates\n",
      "Traceback (most recent call last):\n",
      "  File \"c:\\Users\\Kackie\\anaconda3\\envs\\tensorflow-1.15\\lib\\site-packages\\IPython\\core\\interactiveshell.py\", line 3552, in run_code\n",
      "    exec(code_obj, self.user_global_ns, self.user_ns)\n",
      "  File \"C:\\Users\\Kackie\\AppData\\Local\\Temp\\ipykernel_28924\\3793406994.py\", line 1, in <module>\n",
      "    import tensorflow as tf\n",
      "  File \"c:\\Users\\Kackie\\anaconda3\\envs\\tensorflow-1.15\\lib\\site-packages\\tensorflow\\__init__.py\", line 99, in <module>\n",
      "    from tensorflow_core import *\n",
      "  File \"c:\\Users\\Kackie\\anaconda3\\envs\\tensorflow-1.15\\lib\\site-packages\\tensorflow_core\\__init__.py\", line 28, in <module>\n",
      "    from tensorflow.python import pywrap_tensorflow  # pylint: disable=unused-import\n",
      "  File \"<frozen importlib._bootstrap>\", line 1019, in _handle_fromlist\n",
      "  File \"c:\\Users\\Kackie\\anaconda3\\envs\\tensorflow-1.15\\lib\\site-packages\\tensorflow\\__init__.py\", line 50, in __getattr__\n",
      "    module = self._load()\n",
      "  File \"c:\\Users\\Kackie\\anaconda3\\envs\\tensorflow-1.15\\lib\\site-packages\\tensorflow\\__init__.py\", line 44, in _load\n",
      "    module = _importlib.import_module(self.__name__)\n",
      "  File \"c:\\Users\\Kackie\\anaconda3\\envs\\tensorflow-1.15\\lib\\importlib\\__init__.py\", line 127, in import_module\n",
      "    return _bootstrap._gcd_import(name[level:], package, level)\n",
      "  File \"c:\\Users\\Kackie\\anaconda3\\envs\\tensorflow-1.15\\lib\\site-packages\\tensorflow_core\\python\\__init__.py\", line 52, in <module>\n",
      "    from tensorflow.core.framework.graph_pb2 import *\n",
      "  File \"c:\\Users\\Kackie\\anaconda3\\envs\\tensorflow-1.15\\lib\\site-packages\\tensorflow_core\\core\\framework\\graph_pb2.py\", line 16, in <module>\n",
      "    from tensorflow.core.framework import node_def_pb2 as tensorflow_dot_core_dot_framework_dot_node__def__pb2\n",
      "  File \"c:\\Users\\Kackie\\anaconda3\\envs\\tensorflow-1.15\\lib\\site-packages\\tensorflow_core\\core\\framework\\node_def_pb2.py\", line 16, in <module>\n",
      "    from tensorflow.core.framework import attr_value_pb2 as tensorflow_dot_core_dot_framework_dot_attr__value__pb2\n",
      "  File \"c:\\Users\\Kackie\\anaconda3\\envs\\tensorflow-1.15\\lib\\site-packages\\tensorflow_core\\core\\framework\\attr_value_pb2.py\", line 16, in <module>\n",
      "    from tensorflow.core.framework import tensor_pb2 as tensorflow_dot_core_dot_framework_dot_tensor__pb2\n",
      "  File \"c:\\Users\\Kackie\\anaconda3\\envs\\tensorflow-1.15\\lib\\site-packages\\tensorflow_core\\core\\framework\\tensor_pb2.py\", line 16, in <module>\n",
      "    from tensorflow.core.framework import resource_handle_pb2 as tensorflow_dot_core_dot_framework_dot_resource__handle__pb2\n",
      "  File \"c:\\Users\\Kackie\\anaconda3\\envs\\tensorflow-1.15\\lib\\site-packages\\tensorflow_core\\core\\framework\\resource_handle_pb2.py\", line 16, in <module>\n",
      "    from tensorflow.core.framework import tensor_shape_pb2 as tensorflow_dot_core_dot_framework_dot_tensor__shape__pb2\n",
      "  File \"c:\\Users\\Kackie\\anaconda3\\envs\\tensorflow-1.15\\lib\\site-packages\\tensorflow_core\\core\\framework\\tensor_shape_pb2.py\", line 42, in <module>\n",
      "    serialized_options=None, file=DESCRIPTOR),\n",
      "  File \"c:\\Users\\Kackie\\anaconda3\\envs\\tensorflow-1.15\\lib\\site-packages\\google\\protobuf\\descriptor.py\", line 560, in __new__\n",
      "    _message.Message._CheckCalledFromGeneratedFile()\n",
      "TypeError: Descriptors cannot not be created directly.\n",
      "If this call came from a _pb2.py file, your generated code is out of date and must be regenerated with protoc >= 3.19.0.\n",
      "If you cannot immediately regenerate your protos, some other possible workarounds are:\n",
      " 1. Downgrade the protobuf package to 3.20.x or lower.\n",
      " 2. Set PROTOCOL_BUFFERS_PYTHON_IMPLEMENTATION=python (but this will use pure-Python parsing and will be much slower).\n",
      "\n",
      "More information: https://developers.google.com/protocol-buffers/docs/news/2022-05-06#python-updates\n",
      "\n",
      "During handling of the above exception, another exception occurred:\n",
      "\n",
      "Traceback (most recent call last):\n",
      "  File \"c:\\Users\\Kackie\\anaconda3\\envs\\tensorflow-1.15\\lib\\site-packages\\IPython\\core\\interactiveshell.py\", line 2098, in showtraceback\n",
      "    stb = value._render_traceback_()\n",
      "AttributeError: 'TypeError' object has no attribute '_render_traceback_'\n",
      "\n",
      "During handling of the above exception, another exception occurred:\n",
      "\n",
      "Traceback (most recent call last):\n",
      "  File \"c:\\Users\\Kackie\\anaconda3\\envs\\tensorflow-1.15\\lib\\site-packages\\IPython\\core\\interactiveshell.py\", line 3472, in run_ast_nodes\n",
      "    if (await self.run_code(code, result,  async_=asy)):\n",
      "  File \"c:\\Users\\Kackie\\anaconda3\\envs\\tensorflow-1.15\\lib\\site-packages\\IPython\\core\\interactiveshell.py\", line 3569, in run_code\n",
      "    self.showtraceback(running_compiled_code=True)\n",
      "  File \"c:\\Users\\Kackie\\anaconda3\\envs\\tensorflow-1.15\\lib\\site-packages\\IPython\\core\\interactiveshell.py\", line 2101, in showtraceback\n",
      "    value, tb, tb_offset=tb_offset)\n",
      "  File \"c:\\Users\\Kackie\\anaconda3\\envs\\tensorflow-1.15\\lib\\site-packages\\IPython\\core\\ultratb.py\", line 1368, in structured_traceback\n",
      "    self, etype, value, tb, tb_offset, number_of_lines_of_context)\n",
      "  File \"c:\\Users\\Kackie\\anaconda3\\envs\\tensorflow-1.15\\lib\\site-packages\\IPython\\core\\ultratb.py\", line 1268, in structured_traceback\n",
      "    self, etype, value, tb, tb_offset, number_of_lines_of_context\n",
      "  File \"c:\\Users\\Kackie\\anaconda3\\envs\\tensorflow-1.15\\lib\\site-packages\\IPython\\core\\ultratb.py\", line 1125, in structured_traceback\n",
      "    tb_offset)\n",
      "  File \"c:\\Users\\Kackie\\anaconda3\\envs\\tensorflow-1.15\\lib\\site-packages\\IPython\\core\\ultratb.py\", line 1082, in format_exception_as_a_whole\n",
      "    last_unique, recursion_repeat = find_recursion(orig_etype, evalue, records)\n",
      "  File \"c:\\Users\\Kackie\\anaconda3\\envs\\tensorflow-1.15\\lib\\site-packages\\IPython\\core\\ultratb.py\", line 382, in find_recursion\n",
      "    return len(records), 0\n",
      "TypeError: object of type 'NoneType' has no len()\n",
      "\n",
      "During handling of the above exception, another exception occurred:\n",
      "\n",
      "Traceback (most recent call last):\n",
      "  File \"c:\\Users\\Kackie\\anaconda3\\envs\\tensorflow-1.15\\lib\\site-packages\\IPython\\core\\interactiveshell.py\", line 2098, in showtraceback\n",
      "    stb = value._render_traceback_()\n",
      "AttributeError: 'TypeError' object has no attribute '_render_traceback_'\n",
      "\n",
      "During handling of the above exception, another exception occurred:\n",
      "\n",
      "Traceback (most recent call last):\n",
      "  File \"c:\\Users\\Kackie\\anaconda3\\envs\\tensorflow-1.15\\lib\\site-packages\\IPython\\core\\interactiveshell.py\", line 3029, in _run_cell\n",
      "    return runner(coro)\n",
      "  File \"c:\\Users\\Kackie\\anaconda3\\envs\\tensorflow-1.15\\lib\\site-packages\\IPython\\core\\async_helpers.py\", line 78, in _pseudo_sync_runner\n",
      "    coro.send(None)\n",
      "  File \"c:\\Users\\Kackie\\anaconda3\\envs\\tensorflow-1.15\\lib\\site-packages\\IPython\\core\\interactiveshell.py\", line 3257, in run_cell_async\n",
      "    interactivity=interactivity, compiler=compiler, result=result)\n",
      "  File \"c:\\Users\\Kackie\\anaconda3\\envs\\tensorflow-1.15\\lib\\site-packages\\IPython\\core\\interactiveshell.py\", line 3491, in run_ast_nodes\n",
      "    self.showtraceback()\n",
      "  File \"c:\\Users\\Kackie\\anaconda3\\envs\\tensorflow-1.15\\lib\\site-packages\\IPython\\core\\interactiveshell.py\", line 2101, in showtraceback\n",
      "    value, tb, tb_offset=tb_offset)\n",
      "  File \"c:\\Users\\Kackie\\anaconda3\\envs\\tensorflow-1.15\\lib\\site-packages\\IPython\\core\\ultratb.py\", line 1368, in structured_traceback\n",
      "    self, etype, value, tb, tb_offset, number_of_lines_of_context)\n",
      "  File \"c:\\Users\\Kackie\\anaconda3\\envs\\tensorflow-1.15\\lib\\site-packages\\IPython\\core\\ultratb.py\", line 1268, in structured_traceback\n",
      "    self, etype, value, tb, tb_offset, number_of_lines_of_context\n",
      "  File \"c:\\Users\\Kackie\\anaconda3\\envs\\tensorflow-1.15\\lib\\site-packages\\IPython\\core\\ultratb.py\", line 1143, in structured_traceback\n",
      "    chained_exceptions_tb_offset)\n",
      "  File \"c:\\Users\\Kackie\\anaconda3\\envs\\tensorflow-1.15\\lib\\site-packages\\IPython\\core\\ultratb.py\", line 1082, in format_exception_as_a_whole\n",
      "    last_unique, recursion_repeat = find_recursion(orig_etype, evalue, records)\n",
      "  File \"c:\\Users\\Kackie\\anaconda3\\envs\\tensorflow-1.15\\lib\\site-packages\\IPython\\core\\ultratb.py\", line 382, in find_recursion\n",
      "    return len(records), 0\n",
      "TypeError: object of type 'NoneType' has no len()\n",
      "\n",
      "During handling of the above exception, another exception occurred:\n",
      "\n",
      "Traceback (most recent call last):\n",
      "  File \"c:\\Users\\Kackie\\anaconda3\\envs\\tensorflow-1.15\\lib\\site-packages\\IPython\\core\\interactiveshell.py\", line 2098, in showtraceback\n",
      "    stb = value._render_traceback_()\n",
      "AttributeError: 'TypeError' object has no attribute '_render_traceback_'\n",
      "\n",
      "During handling of the above exception, another exception occurred:\n",
      "\n",
      "Traceback (most recent call last):\n",
      "  File \"c:\\Users\\Kackie\\anaconda3\\envs\\tensorflow-1.15\\lib\\site-packages\\IPython\\core\\ultratb.py\", line 1101, in get_records\n",
      "    return _fixed_getinnerframes(etb, number_of_lines_of_context, tb_offset)\n",
      "  File \"c:\\Users\\Kackie\\anaconda3\\envs\\tensorflow-1.15\\lib\\site-packages\\IPython\\core\\ultratb.py\", line 248, in wrapped\n",
      "    return f(*args, **kwargs)\n",
      "  File \"c:\\Users\\Kackie\\anaconda3\\envs\\tensorflow-1.15\\lib\\site-packages\\IPython\\core\\ultratb.py\", line 281, in _fixed_getinnerframes\n",
      "    records = fix_frame_records_filenames(inspect.getinnerframes(etb, context))\n",
      "  File \"c:\\Users\\Kackie\\anaconda3\\envs\\tensorflow-1.15\\lib\\inspect.py\", line 1502, in getinnerframes\n",
      "    frameinfo = (tb.tb_frame,) + getframeinfo(tb, context)\n",
      "  File \"c:\\Users\\Kackie\\anaconda3\\envs\\tensorflow-1.15\\lib\\inspect.py\", line 1460, in getframeinfo\n",
      "    filename = getsourcefile(frame) or getfile(frame)\n",
      "  File \"c:\\Users\\Kackie\\anaconda3\\envs\\tensorflow-1.15\\lib\\inspect.py\", line 696, in getsourcefile\n",
      "    if getattr(getmodule(object, filename), '__loader__', None) is not None:\n",
      "  File \"c:\\Users\\Kackie\\anaconda3\\envs\\tensorflow-1.15\\lib\\inspect.py\", line 733, in getmodule\n",
      "    if ismodule(module) and hasattr(module, '__file__'):\n",
      "  File \"c:\\Users\\Kackie\\anaconda3\\envs\\tensorflow-1.15\\lib\\site-packages\\tensorflow\\__init__.py\", line 50, in __getattr__\n",
      "    module = self._load()\n",
      "  File \"c:\\Users\\Kackie\\anaconda3\\envs\\tensorflow-1.15\\lib\\site-packages\\tensorflow\\__init__.py\", line 44, in _load\n",
      "    module = _importlib.import_module(self.__name__)\n",
      "  File \"c:\\Users\\Kackie\\anaconda3\\envs\\tensorflow-1.15\\lib\\importlib\\__init__.py\", line 127, in import_module\n",
      "    return _bootstrap._gcd_import(name[level:], package, level)\n",
      "  File \"<frozen importlib._bootstrap>\", line 1006, in _gcd_import\n",
      "  File \"<frozen importlib._bootstrap>\", line 983, in _find_and_load\n",
      "  File \"<frozen importlib._bootstrap>\", line 953, in _find_and_load_unlocked\n",
      "  File \"<frozen importlib._bootstrap>\", line 219, in _call_with_frames_removed\n",
      "  File \"<frozen importlib._bootstrap>\", line 1006, in _gcd_import\n",
      "  File \"<frozen importlib._bootstrap>\", line 983, in _find_and_load\n",
      "  File \"<frozen importlib._bootstrap>\", line 967, in _find_and_load_unlocked\n",
      "  File \"<frozen importlib._bootstrap>\", line 677, in _load_unlocked\n",
      "  File \"<frozen importlib._bootstrap_external>\", line 728, in exec_module\n",
      "  File \"<frozen importlib._bootstrap>\", line 219, in _call_with_frames_removed\n",
      "  File \"c:\\Users\\Kackie\\anaconda3\\envs\\tensorflow-1.15\\lib\\site-packages\\tensorflow_core\\__init__.py\", line 33, in <module>\n",
      "    from tensorflow._api.v1 import audio\n",
      "  File \"c:\\Users\\Kackie\\anaconda3\\envs\\tensorflow-1.15\\lib\\site-packages\\tensorflow_core\\_api\\v1\\audio\\__init__.py\", line 10, in <module>\n",
      "    from tensorflow.python.ops.gen_audio_ops import decode_wav\n",
      "  File \"c:\\Users\\Kackie\\anaconda3\\envs\\tensorflow-1.15\\lib\\site-packages\\tensorflow_core\\python\\ops\\gen_audio_ops.py\", line 11, in <module>\n",
      "    from tensorflow.python.eager import context as _context\n",
      "  File \"c:\\Users\\Kackie\\anaconda3\\envs\\tensorflow-1.15\\lib\\site-packages\\tensorflow_core\\python\\eager\\context.py\", line 29, in <module>\n",
      "    from tensorflow.core.protobuf import config_pb2\n",
      "  File \"c:\\Users\\Kackie\\anaconda3\\envs\\tensorflow-1.15\\lib\\site-packages\\tensorflow_core\\core\\protobuf\\config_pb2.py\", line 16, in <module>\n",
      "    from tensorflow.core.framework import cost_graph_pb2 as tensorflow_dot_core_dot_framework_dot_cost__graph__pb2\n",
      "  File \"c:\\Users\\Kackie\\anaconda3\\envs\\tensorflow-1.15\\lib\\site-packages\\tensorflow_core\\core\\framework\\cost_graph_pb2.py\", line 16, in <module>\n",
      "    from tensorflow.core.framework import tensor_shape_pb2 as tensorflow_dot_core_dot_framework_dot_tensor__shape__pb2\n",
      "  File \"c:\\Users\\Kackie\\anaconda3\\envs\\tensorflow-1.15\\lib\\site-packages\\tensorflow_core\\core\\framework\\tensor_shape_pb2.py\", line 42, in <module>\n",
      "    serialized_options=None, file=DESCRIPTOR),\n",
      "  File \"c:\\Users\\Kackie\\anaconda3\\envs\\tensorflow-1.15\\lib\\site-packages\\google\\protobuf\\descriptor.py\", line 560, in __new__\n",
      "    _message.Message._CheckCalledFromGeneratedFile()\n",
      "TypeError: Descriptors cannot not be created directly.\n",
      "If this call came from a _pb2.py file, your generated code is out of date and must be regenerated with protoc >= 3.19.0.\n",
      "If you cannot immediately regenerate your protos, some other possible workarounds are:\n",
      " 1. Downgrade the protobuf package to 3.20.x or lower.\n",
      " 2. Set PROTOCOL_BUFFERS_PYTHON_IMPLEMENTATION=python (but this will use pure-Python parsing and will be much slower).\n",
      "\n",
      "More information: https://developers.google.com/protocol-buffers/docs/news/2022-05-06#python-updates\n"
     ]
    }
   ],
   "source": [
    "import tensorflow as tf"
   ]
  },
  {
   "cell_type": "code",
   "execution_count": null,
   "metadata": {},
   "outputs": [],
   "source": []
  }
 ],
 "metadata": {
  "kernelspec": {
   "display_name": "Python 3.7.13 ('tensorflow-1.15')",
   "language": "python",
   "name": "python3"
  },
  "language_info": {
   "codemirror_mode": {
    "name": "ipython",
    "version": 3
   },
   "file_extension": ".py",
   "mimetype": "text/x-python",
   "name": "python",
   "nbconvert_exporter": "python",
   "pygments_lexer": "ipython3",
   "version": "3.7.13"
  },
  "orig_nbformat": 4,
  "vscode": {
   "interpreter": {
    "hash": "b0d12e5e5cfd0310816defa803dcce04e8ade6a4539fcd245100c61b0702eef7"
   }
  }
 },
 "nbformat": 4,
 "nbformat_minor": 2
}
